Workbook

Sheet Set up Branco
A1: Produto | B1: KKC205 | C1: KKS205 | D1: KKS250 | E1: KKC227 | F1: KKC233 | G1: KKC273 | H1: KKC290 | I1: KKL205 | J1: KKL276 | K1: CKQ276 | L1: CHD318 | M1: CKQ300 | N1: CNT210 | O1: CNT276 | P1: CKF205 | Q1: CKF227 | R1: CKF233 | S1: CKF250 | T1: CKF276 | U1: CKF285 | V1: CKF312 | W1: CKF332 | X1: CKF360 | Y1: CHD358 | Z1: EWP190 | AA1: EWP175
A2: KKC205 | B2: 0 | C2: 0 | D2: 30 | E2: 20 | F2: 25 | G2: 35 | H2: 40 | I2: 0 | J2: 35 | K2: 35 | L2: 70 | M2: 40 | N2: 0 | O2: 35 | P2: 20 | Q2: 20 | R2: 35 | S2: 40 | T2: 40 | U2: 40 | V2: 50 | W2: 55 | X2: 60 | Y2: 65 | Z2: 30 | AA2: 30
A3: KKS205 | B3: 0 | C3: 0 | D3: 30 | E3: 20 | F3: 25 | G3: 30 | H3: 40 | I3: 0 | J3: 30 | K3: 30 | L3: 60 | M3: 40 | N3: 0 | O3: 30 | P3: 20 | Q3: 35 | R3: 35 | S3: 40 | T3: 40 | U3: 40 | V3: 50 | W3: 55 | X3: 60 | Y3: 65 | Z3: 30 | AA3: 30
A4: KKS250 | B4: 30 | C4: 30 | D4: 0 | E4: 20 | F4: 20 | G4: 20 | H4: 30 | I4: 30 | J4: 30 | K4: 30 | L4: 60 | M4: 30 | N4: 20 | O4: 20 | P4: 30 | Q4: 30 | R4: 20 | S4: 20 | T4: 30 | U4: 40 | V4: 50 | W4: 55 | X4: 60 | Y4: 60 | Z4: 30 | AA4: 30
A5: KKC227 | B5: 20 | C5: 20 | D5: 20 | E5: 0 | F5: 20 | G5: 25 | H5: 30 | I5: 20 | J5: 30 | K5: 30 | L5: 50 | M5: 40 | N5: 20 | O5: 30 | P5: 20 | Q5: 0 | R5: 30 | S5: 20 | T5: 80 | U5: 80 | V5: 80 | W5: 80 | X5: 80 | Y5: 110 | Z5: 45 | AA5: 45
A6: KKC233 | B6: 25 | C6: 20 | D6: 20 | E6: 20 | F6: 0 | G6: 25 | H6: 30 | I6: 25 | J6: 30 | K6: 30 | L6: 40 | M6: 40 | N6: 20 | O6: 30 | P6: 30 | Q6: 0 | R6: 20 | S6: 50 | T6: 80 | U6: 80 | V6: 80 | W6: 80 | X6: 80 | Y6: 100 | Z6: 45 | AA6: 45
A7: KKC273 | B7: 30 | C7: 30 | D7: 20 | E7: 25 | F7: 25 | G7: 0 | H7: 25 | I7: 30 | J7: 0 | K7: 0 | L7: 40 | M7: 40 | N7: 35 | O7: 15 | P7: 30 | Q7: 30 | R7: 25 | S7: 30 | T7: 80 | U7: 80 | V7: 80 | W7: 80 | X7: 80 | Y7: 100 | Z7: 50 | AA7: 50
A8: KKC290 | B8: 30 | C8: 40 | D8: 30 | E8: 30 | F8: 30 | G8: 25 | H8: 0 | I8: 40 | J8: 30 | K8: 30 | L8: 40 | M8: 30 | N8: 40 | O8: 25 | P8: 40 | Q8: 30 | R8: 30 | S8: 40 | T8: 30 | U8: 80 | V8: 80 | W8: 80 | X8: 80 | Y8: 90 | Z8: 50 | AA8: 50
A9: KKL205 | B9: 0 | C9: 0 | D9: 30 | E9: 25 | F9: 25 | G9: 30 | H9: 40 | I9: 0 | J9: 35 | K9: 35 | L9: 70 | M9: 60 | N9: 0 | O9: 35 | P9: 20 | Q9: 35 | R9: 40 | S9: 60 | T9: 80 | U9: 80 | V9: 80 | W9: 80 | X9: 80 | Y9: 130 | Z9: 40 | AA9: 40
A10: KKL276 | B10: 30 | C10: 30 | D10: 30 | E10: 30 | F10: 25 | G10: 0 | H10: 25 | I10: 30 | J10: 0 | K10: 15 | L10: 40 | M10: 40 | N10: 35 | O10: 10 | P10: 30 | Q10: 30 | R10: 25 | S10: 30 | T10: 80 | U10: 80 | V10: 80 | W10: 80 | X10: 80 | Y10: 100 | Z10: 45 | AA10: 45
A11: CKQ276 | B11: 30 | C11: 30 | D11: 30 | E11: 30 | F11: 25 | G11: 0 | H11: 25 | I11: 30 | J11: 0 | K11: 0 | L11: 20 | M11: 15 | N11: 40 | O11: 0 | P11: 30 | Q11: 30 | R11: 25 | S11: 20 | T11: 0 | U11: 40 | V11: 40 | W11: 40 | X11: 40 | Y11: 100 | Z11: 45 | AA11: 45
A12: CKQ300 | B12: 40 | C12: 40 | D12: 30 | E12: 40 | F12: 50 | G12: 40 | H12: 30 | I12: 60 | J12: 40 | K12: 15 | L12: 15 | M12: 0 | N12: 40 | O12: 35 | P12: 60 | Q12: 40 | R12: 35 | S12: 35 | T12: 20 | U12: 20 | V12: 15 | W12: 15 | X12: 40 | Y12: 70 | Z12: 50 | AA12: 50
A13: CNT210 | B13: 0 | C13: 0 | D13: 30 | E13: 20 | F13: 35 | G13: 35 | H13: 40 | I13: 0 | J13: 35 | K13: 40 | L13: 40 | M13: 40 | N13: 0 | O13: 20 | P13: 20 | Q13: 30 | R13: 35 | S13: 40 | T13: 40 | U13: 50 | V13: 50 | W13: 60 | X13: 60 | Y13: 120 | Z13: 40 | AA13: 40
... A35: EKW175 | B35: 80 | C35: 80 | D35: 80 | E35: 80 | F35: 80 | G35: 80 | H35: 90 | I35: 80 | J35: 80 | K35: 80 | L35: 90 | M35: 80 | N35: 80 | O35: 80 | P35: 80 | Q35: 80 | R35: 80 | S35: 80 | T35: 80 | U35: 90 | V35: 90 | W35: 90 | X35: 90 | Y35: 90 | Z35: 50 | AA35: 50

Sheet Set up Kraft
A1: Produto | B1: K28135 | C1: K28150 | D1: K28170 | E1: K28200 | F1: LWE175 | G1: EWC175 | H1: EWC190
A2: K28135 | B2: 0 | C2: 15 | D2: 30 | E2: 40 | F2: 60 | G2: 70 | H2: 80
A3: K28150 | B3: 15 | C3: 0 | D3: 20 | E3: 30 | F3: 50 | G3: 40 | H3: 60
A4: K28170 | B4: 30 | C4: 20 | D4: 0 | E4: 15 | F4: 40 | G4: 40 | H4: 60
A5: K28200 | B5: 40 | C5: 30 | D5: 15 | E5: 0 | F5: 40 | G5: 40 | H5: 60
A6: LWE175 | B6: 70 | C6: 40 | D6: 40 | E6: 40 | F6: 0 | G6: 20 | H6: 30
A7: EWC175 | B7: 70 | C7: 40 | D7: 40 | E7: 60 | F7: 20 | G7: 0 | H7: 20
A8: EWC190 | B8: 80 | C8: 50 | D8: 50 | E8: 60 | F8: 30 | G8: 20 | H8: 0

Sheet De_Para
B1: De>Para | C1: (t)
B2: CHD318>CHD318 | C2: 0
B3: CHD318>CHD358 | C3: 30
B4: CHD318>CKF205 | C4: 70
B5: CHD318>CKF227 | C5: 70
B6: CHD318>CKF233 | C6: 70
B7: CHD318>CKF250 | C7: 60
B8: CHD318>CKF276 | C8: 60
B9: CHD318>CKF285 | C9: 60
B10: CHD318>CKF312 | C10: 60
B11: CHD318>CKF332 | C11: 40
B12: CHD318>CKF360 | C12: 40
B13: CHD318>CKQ276 | C13: 80
... B27: CHD318>KKL205 | C27: 120
B28: CHD318>KKL276 | C28: 80 | AB28: 60 | AD28: 30
B29: CHD318>KKS205 | C29: 120 | AB29: 30 | AD29: 0
B30: CHD318>KKS250 | C30: 60 | AB30: 0 | AD30: 120
B31: CHD318>WTP300 | C31: 240 | AB31: 120 | AD31: 100
B32: CHD358>CHD318 | C32: 30 | AB32: 100 | AD32: 80
B33: CHD358>CHD358 | C33: 0 | AB33: 80 | AD33: 80
B34: CHD358>CKF205 | C34: 120 | AB34: 80 | AD34: 70
B35: CHD358>CKF227 | C35: 100 | AB35: 70 | AD35: 70
B36: CHD358>CKF233 | C36: 80 | AB36: 70 | AD36: 60
B37: CHD358>CKF250 | C37: 80 | AB37: 60 | AD37: 50
B38: CHD358>CKF276 | C38: 70 | AB38: 50 | AD38: 50
B39: CHD358>CKF285 | C39: 70 | AB39: 50 | AD39: 100
... B124: CKF233>CNT210 | C124: 35 | AB124: 65 | AD124: 65
B125: CKF233>CNT276 | C125: 35 | AB125: 65
B126: CKF233>EKW200 | C126: 80 | AB126: 70 | AD126: 40
B127: CKF233>EWC190 | C127: 65 | AB127: 40 | AD127: 30
B128: CKF233>EWP175 | C128: 65 | AB128: 30 | AD128: 0
B129: CKF233>EWP190 | C129: 65 | AB129: 0 | AD129: 25
B130: CKF233>K28150 | C130: 70 | AB130: 25 | AD130: 30
B131: CKF233>KKC205 | C131: 40 | AB131: 30 | AD131: 40
B132: CKF233>KKC227 | C132: 30 | AB132: 40 | AD132: 25
B133: CKF233>KKC233 | C133: 0 | AB133: 25 | AD133: 40
B134: CKF233>KKC273 | C134: 25 | AB134: 40 | AD134: 20
B135: CKF233>KKC290 | C135: 30 | AB135: 20
B136: CKF233>KKL200 | C136: 60 | AB136: 180 | AD136: 40
B137: CKF233>KKL205 | C137: 40 | AB137: 40 | AD137: 80
...

Sheet Gráfico1

Sheet Gráfico2

Sheet Perda estimada
A1: Mês | B1: Data Setup | C1: De | D1: Para | E1: Tempo | F1: De>Para | G1: Perda estimada
A2: =MONTH(B2) -> 1 | B2: 45658.1 | C2: LLE150 | D2: LLE170 | E2: 0.046516204 | F2: =CONCATENATE(C2,">",D2) -> LLE150>LLE170 | G2: =VLOOKUP(F2,De_Para!$B$2:$C$1500,2,0) -> 60
A3: =MONTH(B3) -> 1 | B3: 45660.99 | C3: LLE170 | D3: K28200 | E3: 0.082465278 | F3: =CONCATENATE(C3,">",D3) -> LLE170>K28200 | G3: =VLOOKUP(F3,De_Para!$B$2:$C$1500,2,0) -> 60 | L3: Mês | M3: Contagem de De | N3: Soma de Perda estimada | O3: Custo
A4: =MONTH(B4) -> 1 | B4: 45662.067 | C4: K28200 | D4: LLE170 | E4: 0.71538194 | F4: =CONCATENATE(C4,">",D4) -> K28200>LLE170 | G4: =VLOOKUP(F4,De_Para!$B$2:$C$1500,2,0) -> 60 | L4: 1 | M4: 28 | N4: 1460 | O4: =GETPIVOTDATA("Soma de Perda estimada",$L$3,"Mês",1)*M28 -> 3160900
A5: =MONTH(B5) -> 1 | B5: 45662.975 | C5: LLE170 | D5: K28200 | E5: 0.040046296 | F5: =CONCATENATE(C5,">",D5) -> LLE170>K28200 | G5: =VLOOKUP(F5,De_Para!$B$2:$C$1500,2,0) -> 60 | L5: 2 | M5: 27 | N5: 1430 | O5: =$M$28*GETPIVOTDATA("Soma de Perda estimada",$L$3,"Mês",L5) -> 3095950
A6: =MONTH(B6) -> 1 | B6: 45664.78 | C6: LLE200 | D6: LLE170 | E6: 0.016956019 | F6: =CONCATENATE(C6,">",D6) -> LLE200>LLE170 | G6: =VLOOKUP(F6,De_Para!$B$2:$C$1500,2,0) -> 60 | L6: 3 | M6: 25 | N6: 1455 | O6: =$M$28*GETPIVOTDATA("Soma de Perda estimada",$L$3,"Mês",L6) -> 3150075
A7: =MONTH(B7) -> 1 | B7: 45665.417 | C7: LLE170 | D7: LWE175 | E7: 0.008912037 | F7: =CONCATENATE(C7,">",D7) -> LLE170>LWE175 | G7: =VLOOKUP(F7,De_Para!$B$2:$C$1500,2,0) -> 100 | L7: 4 | M7: 26 | N7: 1145 | O7: =$M$28*GETPIVOTDATA("Soma de Perda estimada",$L$3,"Mês",L7) -> 2478925
A8: =MONTH(B8) -> 1 | B8: 45665.886 | C8: EKW175 | D8: EKW200 | E8: 0.04224537 | F8: =CONCATENATE(C8,">",D8) -> EKW175>EKW200 | G8: =VLOOKUP(F8,De_Para!$B$2:$C$1500,2,0) -> 50 | L8: 5 | M8: 35 | N8: 2175 | O8: =$M$28*GETPIVOTDATA("Soma de Perda estimada",$L$3,"Mês",L8) -> 4708875
A9: =MONTH(B9) -> 1 | B9: 45666.083 | C9: EKW200 | D9: CKF205 | E9: 0.11260417 | F9: =CONCATENATE(C9,">",D9) -> EKW200>CKF205 | G9: =VLOOKUP(F9,De_Para!$B$2:$C$1500,2,0) -> 50 | L9: 6 | M9: 18 | N9: 795 | O9: =$M$28*GETPIVOTDATA("Soma de Perda estimada",$L$3,"Mês",L9) -> 1721175
A10: =MONTH(B10) -> 1 | B10: 45667.214 | C10: CKF205 | D10: KKL195 | E10: 0.008275463 | F10: =CONCATENATE(C10,">",D10) -> CKF205>KKL195 | G10: =VLOOKUP(F10,De_Para!$B$2:$C$1500,2,0) -> 0 | L10: 7 | M10: 25 | N10: 1370 | O10: =$M$28*GETPIVOTDATA("Soma de Perda estimada",$L$3,"Mês",L10) -> 2966050
A11: =MONTH(B11) -> 1 | B11: 45668.137 | C11: KKL195 | D11: K28170 | E11: 0.044618056 | F11: =CONCATENATE(C11,">",D11) -> KKL195>K28170 | G11: =VLOOKUP(F11,De_Para!$B$2:$C$1500,2,0) -> 30 | L11: 8 | M11: 21 | N11: 1255 | O11: =$M$28*GETPIVOTDATA("Soma de Perda estimada",$L$3,"Mês",L11) -> 2717075
A12: =MONTH(B12) -> 1 | B12: 45669.141 | C12: K28170 | D12: LLE150 | E12: 0.027488426 | F12: =CONCATENATE(C12,">",D12) -> K28170>LLE150 | G12: =VLOOKUP(F12,De_Para!$B$2:$C$1500,2,0) -> 60 | L12: 9 | M12: 30 | N12: 2175 | O12: =$M$28*GETPIVOTDATA("Soma de Perda estimada",$L$3,"Mês",L12) -> 4708875
A13: =MONTH(B13) -> 1 | B13: 45672.466 | C13: LLE150 | D13: LLE200 | E13: 2.3051273 | F13: =CONCATENATE(C13,">",D13) -> LLE150>LLE200 | G13: =VLOOKUP(F13,De_Para!$B$2:$C$1500,2,0) -> 60 | L13: 10 | M13: 27 | N13: 1875 | O13: =$M$28*GETPIVOTDATA("Soma de Perda estimada",$L$3,"Mês",L13) -> 4059375
A14: =MONTH(B14) -> 1 | B14: 45672.865 | C14: LLE200 | D14: LLE170 | E14: 0.047291667 | F14: =CONCATENATE(C14,">",D14) -> LLE200>LLE170 | G14: =VLOOKUP(F14,De_Para!$B$2:$C$1500,2,0) -> 60 | L14: 11 | M14: 11 | N14: 475 | O14: =$M$28*GETPIVOTDATA("Soma de Perda estimada",$L$3,"Mês",L14) -> 1028375
A15: =MONTH(B15) -> 1 | B15: 45673.384 | C15: LLE170 | D15: KKL195 | E15: 0.11956019 | F15: =CONCATENATE(C15,">",D15) -> LLE170>KKL195 | G15: =VLOOKUP(F15,De_Para!$B$2:$C$1500,2,0) -> 120 | L15: 12 | M15: 22 | N15: 1975 | O15: =$M$28*GETPIVOTDATA("Soma de Perda estimada",$L$3,"Mês",L15) -> 4275875
A16: =MONTH(B16) -> 1 | B16: 45674.219 | C16: KKL195 | D16: LLE150 | E16: 0.052361111 | F16: =CONCATENATE(C16,">",D16) -> KKL195>LLE150 | G16: =VLOOKUP(F16,De_Para!$B$2:$C$1500,2,0) -> 120 | L16: Total Resultado | M16: 295 | N16: 17585 | O16: =SUM(O4:O15) -> 38071525
A17: =MONTH(B17) -> 1 | B17: 45674.962 | C17: LLE150 | D17: LLE170 | E17: 0.050578704 | F17: =CONCATENATE(C17,">",D17) -> LLE150>LLE170 | G17: =VLOOKUP(F17,De_Para!$B$2:$C$1500,2,0) -> 60
A18: =MONTH(B18) -> 1 | B18: 45675.784 | C18: LLE170 | D18: CKQ276 | E18: 0.31649306 | F18: =CONCATENATE(C18,">",D18) -> LLE170>CKQ276 | G18: =VLOOKUP(F18,De_Para!$B$2:$C$1500,2,0) -> 100
A19: =MONTH(B19) -> 1 | B19: 45677.316 | C19: CKQ276 | D19: CKQ300 | E19: 0.039421296 | F19: =CONCATENATE(C19,">",D19) -> CKQ276>CKQ300 | G19: =VLOOKUP(F19,De_Para!$B$2:$C$1500,2,0) -> 15
A20: =MONTH(B20) -> 1 | B20: 45678.291 | C20: CKQ300 | D20: CHD318 | E20: 0.025462963 | F20: =CONCATENATE(C20,">",D20) -> CKQ300>CHD318 | G20: =VLOOKUP(F20,De_Para!$B$2:$C$1500,2,0) -> 15
A21: =MONTH(B21) -> 1 | B21: 45681.654 | C21: CHD318 | D21: CKF250 | E21: 0.034016204 | F21: =CONCATENATE(C21,">",D21) -> CHD318>CKF250 | G21: =VLOOKUP(F21,De_Para!$B$2:$C$1500,2,0) -> 60
A22: =MONTH(B22) -> 1 | B22: 45682.688 | C22: CKF250 | D22: CKF312 | E22: 0.03275463 | F22: =CONCATENATE(C22,">",D22) -> CKF250>CKF312 | G22: =VLOOKUP(F22,De_Para!$B$2:$C$1500,2,0) -> 20 | L22: OEE | M22: =M23*M24*M25 -> 0.64313771 | N22: =N23*N24*N25 -> 0.61795379
A23: =MONTH(B23) -> 1 | B23: 45683.729 | C23: CKF312 | D23: CKF285 | E23: 0.03275463 | F23: =CONCATENATE(C23,">",D23) -> CKF312>CKF285 | G23: =VLOOKUP(F23,De_Para!$B$2:$C$1500,2,0) -> 15 | L23: Disponibilidade | M23: 0.8326 | N23: 0.8326
A24: =MONTH(B24) -> 1 | B24: 45684.007 | C24: CKF285 | D24: CKF233 | E24: 0.038020833 | F24: =CONCATENATE(C24,">",D24) -> CKF285>CKF233 | G24: =VLOOKUP(F24,De_Para!$B$2:$C$1500,2,0) -> 30 | L24: Performance | M24: 0.8131 | N24: 0.8131
A25: =MONTH(B25) -> 1 | B25: 45685.53 | C25: CKF233 | D25: EWP190 | E25: 0.034363426 | F25: =CONCATENATE(C25,">",D25) -> CKF233>EWP190 | G25: =VLOOKUP(F25,De_Para!$B$2:$C$1500,2,0) -> 65 | L25: Rendimento | M25: 0.95 | N25: 0.9128
A26: =MONTH(B26) -> 1 | B26: 45686.539 | C26: EWP190 | D26: EWC190 | E26: 0.21457176 | F26: =CONCATENATE(C26,">",D26) -> EWP190>EWC190 | G26: =VLOOKUP(F26,De_Para!$B$2:$C$1500,2,0) -> 0
A27: =MONTH(B27) -> 1 | B27: 45686.746 | C27: EWC190 | D27: EKW175 | E27: 0.029456019 | F27: =CONCATENATE(C27,">",D27) -> EWC190>EKW175 | G27: =VLOOKUP(F27,De_Para!$B$2:$C$1500,2,0) -> 10
A28: =MONTH(B28) -> 1 | B28: 45688.205 | C28: EKW175 | D28: LLE170 | E28: 0.054224537 | F28: =CONCATENATE(C28,">",D28) -> EKW175>LLE170 | G28: =VLOOKUP(F28,De_Para!$B$2:$C$1500,2,0) -> 120 | M28: 2165 | AB28: WTP265 | AC28: WTP220
A29: =MONTH(B29) -> 1 | B29: 45688.87 | C29: LLE170 | D29: K28170 | E29: 0.047569444 | F29: =CONCATENATE(C29,">",D29) -> LLE170>K28170 | G29: =VLOOKUP(F29,De_Para!$B$2:$C$1500,2,0) -> 0 | AB29: WTP220 | AC29: WTP205
A30: =MONTH(B30) -> 2 | B30: 45689.733 | C30: K28170 | D30: LLE170 | E30: 0.046944444 | F30: =CONCATENATE(C30,">",D30) -> K28170>LLE170 | G30: =VLOOKUP(F30,De_Para!$B$2:$C$1500,2,0) -> 0 | AB30: WTP205 | AC30: EKW200
A31: =MONTH(B31) -> 2 | B31: 45690.444 | C31: LLE170 | D31: K28150 | E31: 0.050115741 | F31: =CONCATENATE(C31,">",D31) -> LLE170>K28150 | G31: =VLOOKUP(F31,De_Para!$B$2:$C$1500,2,0) -> 60 | AB31: EKW200 | AC31: K28150
A32: =MONTH(B32) -> 2 | B32: 45691.7 | C32: K28150 | D32: LLE200 | E32: 0.040335648 | F32: =CONCATENATE(C32,">",D32) -> K28150>LLE200 | G32: =VLOOKUP(F32,De_Para!$B$2:$C$1500,2,0) -> 60 | AB32: K28150 | AC32: EKW200
A33: =MONTH(B33) -> 2 | B33: 45692.92 | C33: K28200 | D33: KKL195 | E33: 0.04537037 | F33: =CONCATENATE(C33,">",D33) -> K28200>KKL195 | G33: =VLOOKUP(F33,De_Para!$B$2:$C$1500,2,0) -> 90 | AB33: EKW200 | AC33: EKW175
A34: =MONTH(B34) -> 2 | B34: 45693.664 | C34: KKL195 | D34: WUP250 | E34: 0.042650463 | F34: =CONCATENATE(C34,">",D34) -> KKL195>WUP250 | G34: =VLOOKUP(F34,De_Para!$B$2:$C$1500,2,0) -> 260 | L34: Mês | M34: N° de setups | N34: Perda estimada (t) | O34: Custo Estimado | AB34: EKW175 | AC34: CHD318
A35: =MONTH(B35) -> 2 | B35: 45694.227 | C35: WUP250 | D35: WTP265 | E35: 0.038020833 | F35: =CONCATENATE(C35,">",D35) -> WUP250>WTP265 | G35: =VLOOKUP(F35,De_Para!$B$2:$C$1500,2,0) -> 30 | L35: Janeiro | M35: 28 | N35: 1460 | O35: 3160900 | AB35: CHD318 | AC35: CKQ300
A36: =MONTH(B36) -> 2 | B36: 45694.725 | C36: WTP265 | D36: WTP220 | E36: 0.038020833 | F36: =CONCATENATE(C36,">",D36) -> WTP265>WTP220 | G36: =VLOOKUP(F36,De_Para!$B$2:$C$1500,2,0) -> 30 | L36: Fevereiro | M36: 27 | N36: 1430 | O36: 3095950 | AB36: CKQ300 | AC36: K28150
A37: =MONTH(B37) -> 2 | B37: 45695.127 | C37: WTP220 | D37: WTP205 | E37: 0.037789352 | F37: =CONCATENATE(C37,">",D37) -> WTP220>WTP205 | G37: =VLOOKUP(F37,De_Para!$B$2:$C$1500,2,0) -> 30 | L37: Março | M37: 25 | N37: 1455 | O37: 3150075 | AB37: K28150 | AC37: CKF312
A38: =MONTH(B38) -> 2 | B38: 45695.465 | C38: WTP205 | D38: EKW200 | E38: 0.037835648 | F38: =CONCATENATE(C38,">",D38) -> WTP205>EKW200 | G38: =VLOOKUP(F38,De_Para!$B$2:$C$1500,2,0) -> 130 | L38: Abril | M38: 26 | N38: 1145 | O38: 2478925 | AB38: CKF312 | AC38: CKF285
A39: =MONTH(B39) -> 2 | B39: 45696.836 | C39: EKW200 | D39: K28150 | E39: 0.051516204 | F39: =CONCATENATE(C39,">",D39) -> EKW200>K28150 | G39: =VLOOKUP(F39,De_Para!$B$2:$C$1500,2,0) -> 65 | L39: Maio | M39: 35 | N39: 2175 | O39: 4708875 | AB39: CKF285 | AC39: CKF250
A40: =MONTH(B40) -> 2 | B40: 45697.635 | C40: K28150 | D40: EKW200 | E40: 0.14797454 | F40: =CONCATENATE(C40,">",D40) -> K28150>EKW200 | G40: =VLOOKUP(F40,De_Para!$B$2:$C$1500,2,0) -> 65 | L40: Junho | M40: 18 | N40: 795 | O40: 1721175 | AB40: CKF250 | AC40: CKF233
...

Sheet Orçamento
G33: Janeiro | H33: Fevereiro | I33: Março | J33: Abril | K33: Maio | L33: Junho | M33: Julho | N33: Agosto | O33: Setembro | P33: Outubro | Q33: Novembro | R33: Dezembro | S33: Total
F34: Orçamento | G34: 32879 | H34: 30334 | I34: 33923 | J34: 34962 | K34: 35040 | L34: 36116 | M34: 37950 | N34: 38239 | O34: 37423 | P34: 39381 | Q34: 20171 | R34: 39332 | S34: =SUM(G34:R34) -> 415750
F36: Produção Bruta
